2024-04-11 19:15:13 - INFO - num_jobs
2024-04-11 19:15:13 - ERROR - Exception on /api/num_jobs [GET]
Traceback (most recent call last):
  File "/home/alu/.local/lib/python3.10/site-packages/flask/app.py", line 1473, in wsgi_app
    response = self.full_dispatch_request()
  File "/home/alu/.local/lib/python3.10/site-packages/flask/app.py", line 882, in full_dispatch_request
    rv = self.handle_user_exception(e)
  File "/home/alu/.local/lib/python3.10/site-packages/flask/app.py", line 880, in full_dispatch_request
    rv = self.dispatch_request()
  File "/home/alu/.local/lib/python3.10/site-packages/flask/app.py", line 865, in dispatch_request
    return self.ensure_sync(self.view_functions[rule.endpoint])(**view_args)  # type: ignore[no-any-return]
  File "/home/alu/proj/felicia/__init__.py", line 37, in get_response_count
    for file in os.listdir('app/results'):
NameError: name 'os' is not defined
2024-04-11 19:15:54 - INFO - num_jobs
2024-04-11 19:15:54 - ERROR - Exception on /api/num_jobs [GET]
Traceback (most recent call last):
  File "/home/alu/.local/lib/python3.10/site-packages/flask/app.py", line 1473, in wsgi_app
    response = self.full_dispatch_request()
  File "/home/alu/.local/lib/python3.10/site-packages/flask/app.py", line 882, in full_dispatch_request
    rv = self.handle_user_exception(e)
  File "/home/alu/.local/lib/python3.10/site-packages/flask/app.py", line 880, in full_dispatch_request
    rv = self.dispatch_request()
  File "/home/alu/.local/lib/python3.10/site-packages/flask/app.py", line 865, in dispatch_request
    return self.ensure_sync(self.view_functions[rule.endpoint])(**view_args)  # type: ignore[no-any-return]
  File "/home/alu/proj/felicia/__init__.py", line 37, in get_response_count
    running_tasks = 0
NameError: name 'os' is not defined
2024-04-11 19:16:00 - INFO - num_jobs
2024-04-11 19:16:00 - ERROR - Exception on /api/num_jobs [GET]
Traceback (most recent call last):
  File "/home/alu/.local/lib/python3.10/site-packages/flask/app.py", line 1473, in wsgi_app
    response = self.full_dispatch_request()
  File "/home/alu/.local/lib/python3.10/site-packages/flask/app.py", line 882, in full_dispatch_request
    rv = self.handle_user_exception(e)
  File "/home/alu/.local/lib/python3.10/site-packages/flask/app.py", line 880, in full_dispatch_request
    rv = self.dispatch_request()
  File "/home/alu/.local/lib/python3.10/site-packages/flask/app.py", line 865, in dispatch_request
    return self.ensure_sync(self.view_functions[rule.endpoint])(**view_args)  # type: ignore[no-any-return]
  File "/home/alu/proj/felicia/__init__.py", line 38, in get_response_count
    for file in os.listdir('app/results'):
FileNotFoundError: [Errno 2] No such file or directory: 'app/results'
2024-04-11 19:16:02 - INFO - num_jobs
2024-04-11 19:16:02 - ERROR - Exception on /api/num_jobs [GET]
Traceback (most recent call last):
  File "/home/alu/.local/lib/python3.10/site-packages/flask/app.py", line 1473, in wsgi_app
    response = self.full_dispatch_request()
  File "/home/alu/.local/lib/python3.10/site-packages/flask/app.py", line 882, in full_dispatch_request
    rv = self.handle_user_exception(e)
  File "/home/alu/.local/lib/python3.10/site-packages/flask/app.py", line 880, in full_dispatch_request
    rv = self.dispatch_request()
  File "/home/alu/.local/lib/python3.10/site-packages/flask/app.py", line 865, in dispatch_request
    return self.ensure_sync(self.view_functions[rule.endpoint])(**view_args)  # type: ignore[no-any-return]
  File "/home/alu/proj/felicia/__init__.py", line 38, in get_response_count
    for file in os.listdir('app/results'):
FileNotFoundError: [Errno 2] No such file or directory: 'app/results'
2024-04-11 19:16:02 - INFO - num_jobs
2024-04-11 19:16:02 - ERROR - Exception on /api/num_jobs [GET]
Traceback (most recent call last):
  File "/home/alu/.local/lib/python3.10/site-packages/flask/app.py", line 1473, in wsgi_app
    response = self.full_dispatch_request()
  File "/home/alu/.local/lib/python3.10/site-packages/flask/app.py", line 882, in full_dispatch_request
    rv = self.handle_user_exception(e)
  File "/home/alu/.local/lib/python3.10/site-packages/flask/app.py", line 880, in full_dispatch_request
    rv = self.dispatch_request()
  File "/home/alu/.local/lib/python3.10/site-packages/flask/app.py", line 865, in dispatch_request
    return self.ensure_sync(self.view_functions[rule.endpoint])(**view_args)  # type: ignore[no-any-return]
  File "/home/alu/proj/felicia/__init__.py", line 38, in get_response_count
    for file in os.listdir('app/results'):
FileNotFoundError: [Errno 2] No such file or directory: 'app/results'
2024-04-11 19:16:03 - INFO - num_jobs
2024-04-11 19:16:03 - ERROR - Exception on /api/num_jobs [GET]
Traceback (most recent call last):
  File "/home/alu/.local/lib/python3.10/site-packages/flask/app.py", line 1473, in wsgi_app
    response = self.full_dispatch_request()
  File "/home/alu/.local/lib/python3.10/site-packages/flask/app.py", line 882, in full_dispatch_request
    rv = self.handle_user_exception(e)
  File "/home/alu/.local/lib/python3.10/site-packages/flask/app.py", line 880, in full_dispatch_request
    rv = self.dispatch_request()
  File "/home/alu/.local/lib/python3.10/site-packages/flask/app.py", line 865, in dispatch_request
    return self.ensure_sync(self.view_functions[rule.endpoint])(**view_args)  # type: ignore[no-any-return]
  File "/home/alu/proj/felicia/__init__.py", line 38, in get_response_count
    for file in os.listdir('app/results'):
FileNotFoundError: [Errno 2] No such file or directory: 'app/results'
2024-04-11 19:16:03 - INFO - num_jobs
2024-04-11 19:16:03 - ERROR - Exception on /api/num_jobs [GET]
Traceback (most recent call last):
  File "/home/alu/.local/lib/python3.10/site-packages/flask/app.py", line 1473, in wsgi_app
    response = self.full_dispatch_request()
  File "/home/alu/.local/lib/python3.10/site-packages/flask/app.py", line 882, in full_dispatch_request
    rv = self.handle_user_exception(e)
  File "/home/alu/.local/lib/python3.10/site-packages/flask/app.py", line 880, in full_dispatch_request
    rv = self.dispatch_request()
  File "/home/alu/.local/lib/python3.10/site-packages/flask/app.py", line 865, in dispatch_request
    return self.ensure_sync(self.view_functions[rule.endpoint])(**view_args)  # type: ignore[no-any-return]
  File "/home/alu/proj/felicia/__init__.py", line 38, in get_response_count
    for file in os.listdir('app/results'):
FileNotFoundError: [Errno 2] No such file or directory: 'app/results'
2024-04-11 19:16:03 - INFO - num_jobs
2024-04-11 19:16:03 - ERROR - Exception on /api/num_jobs [GET]
Traceback (most recent call last):
  File "/home/alu/.local/lib/python3.10/site-packages/flask/app.py", line 1473, in wsgi_app
    response = self.full_dispatch_request()
  File "/home/alu/.local/lib/python3.10/site-packages/flask/app.py", line 882, in full_dispatch_request
    rv = self.handle_user_exception(e)
  File "/home/alu/.local/lib/python3.10/site-packages/flask/app.py", line 880, in full_dispatch_request
    rv = self.dispatch_request()
  File "/home/alu/.local/lib/python3.10/site-packages/flask/app.py", line 865, in dispatch_request
    return self.ensure_sync(self.view_functions[rule.endpoint])(**view_args)  # type: ignore[no-any-return]
  File "/home/alu/proj/felicia/__init__.py", line 38, in get_response_count
    for file in os.listdir('app/results'):
FileNotFoundError: [Errno 2] No such file or directory: 'app/results'
2024-04-11 19:16:04 - INFO - num_jobs
2024-04-11 19:16:04 - ERROR - Exception on /api/num_jobs [GET]
Traceback (most recent call last):
  File "/home/alu/.local/lib/python3.10/site-packages/flask/app.py", line 1473, in wsgi_app
    response = self.full_dispatch_request()
  File "/home/alu/.local/lib/python3.10/site-packages/flask/app.py", line 882, in full_dispatch_request
    rv = self.handle_user_exception(e)
  File "/home/alu/.local/lib/python3.10/site-packages/flask/app.py", line 880, in full_dispatch_request
    rv = self.dispatch_request()
  File "/home/alu/.local/lib/python3.10/site-packages/flask/app.py", line 865, in dispatch_request
    return self.ensure_sync(self.view_functions[rule.endpoint])(**view_args)  # type: ignore[no-any-return]
  File "/home/alu/proj/felicia/__init__.py", line 38, in get_response_count
    for file in os.listdir('app/results'):
FileNotFoundError: [Errno 2] No such file or directory: 'app/results'
2024-04-11 19:16:05 - INFO - num_jobs
2024-04-11 19:16:05 - ERROR - Exception on /api/num_jobs [GET]
Traceback (most recent call last):
  File "/home/alu/.local/lib/python3.10/site-packages/flask/app.py", line 1473, in wsgi_app
    response = self.full_dispatch_request()
  File "/home/alu/.local/lib/python3.10/site-packages/flask/app.py", line 882, in full_dispatch_request
    rv = self.handle_user_exception(e)
  File "/home/alu/.local/lib/python3.10/site-packages/flask/app.py", line 880, in full_dispatch_request
    rv = self.dispatch_request()
  File "/home/alu/.local/lib/python3.10/site-packages/flask/app.py", line 865, in dispatch_request
    return self.ensure_sync(self.view_functions[rule.endpoint])(**view_args)  # type: ignore[no-any-return]
  File "/home/alu/proj/felicia/__init__.py", line 38, in get_response_count
    for file in os.listdir('app/results'):
FileNotFoundError: [Errno 2] No such file or directory: 'app/results'
2024-04-11 19:16:42 - INFO - jobs
